Workbook
Name ENUM_BOOLEAN: [1]ENUM!#REF!
Name ENUM_BOOLEAN: ENUM!$A$2:$B$3
Name ENUM_CLK_MODE: [1]ENUM!$A$2:$B$4
Name ENUM_CLK_MODE: ENUM!$A$6:$B$8
Name ENUM_VOLTAGE_RAIL: [1]ENUM!$A$7:$B$17
Name ENUM_VOLTAGE_RAIL: ENUM!$A$11:$B$21
Name MC_CLK_MAX: ALC!$C$7
Name MC_CLK_MIN: [1]ALC!$C$6
Name MC_CLK_MIN: ALC!$C$6
Name MC_POLICY_COL_ABSR: 4
Name MC_POLICY_COL_CSPD: 2
Name MC_POLICY_COL_IPT: 3
Name MC_POLICY_TABLE: [1]ALC!$E$6:$H$9
Name MC_POLICY_TABLE: ALC!$E$6:$H$9
Name PMIC_MODE_COL_CX: 2
Name PMIC_MODE_COL_VDD1: 8
Name PMIC_MODE_COL_VDD2: 6
Name PMIC_MODE_COL_VDDA: 3
Name PMIC_MODE_COL_VDDA_LDO_HV: 5
Name PMIC_MODE_COL_VDDA_PLL: 4
Name PMIC_MODE_COL_VDDQ: 7
Name S3_COL_ENTRY: 2
Name S3_COL_EXIT: 3
Name S3_TABLE: [1]ALC!$J$6:$L$8
Name S3_TABLE: ALC!$J$6:$L$8
Name VOLTAGE_RAIL_TABLE: ENUM!$A$11:$B$21

Sheet C
A1: Qualcomm
A2: Qualcomm Technologies, Inc.
A4: DSF XL File
A6: Confidential and Proprietary – Qualcomm Technologies, Inc.
A7: NO PUBLIC DISCLOSURE PERMITTED: Please report postings of this document on public servers or websites to: DocCtrlAgent@qualcomm.com
A8: Restricted Distribution: Not to be distributed to anyone who is not an employee of either Qualcomm Technologies, Inc. or its affiliated companies without the express approval of Qualcomm Configuration Management.
A9: Not to be used, copied, reproduced, or modified in whole or in part, nor its contents revealed in any manner to others without the express written permission of Qualcomm Technologies, Inc.
A11: Qualcomm is a trademark of Qualcomm Incorporated, registered in the United States and other countries. Other product and brand names may be trademarks or registered trademarks of their respective owners.
A12: This technical data may be subject to U.S. and international export, re-export, or transfer (“export”) laws. Diversion contrary to U.S. and international law is strictly prohibited.
A14: Qualcomm Technologies, Inc.
A15: 5775 Morehouse Drive
A16: San Diego, CA 92121
... A19: © 2017 Qualcomm Technologies, Inc. All rights reserved.

Sheet STRUCT
A1: 0 | B1: 1 | C1: 2 | D1: 3 | E1: 4 | F1: 5 | G1: 6 | H1: 7 | I1: 8 | J1: 9 | K1: 10 | L1: 11
A2: 0 | B2: 1 | C2: 2 | D2: 3 | E2: 4 | F2: 5 | G2: 6 | H2: 7 | I2: 8 | J2: 9 | K2: 10 | L2: 11
A3: 0 | B3: 100 | C3: 200 | D3: 300 | E3: 451.2 | F3: 547.2 | G3: 681.6 | H3: 768 | I3: 1017.6 | J3: 1353.6 | K3: 1555.2 | L3: 1804.8
A4: =2^32-1 -> 4294967295 | B4: =1000000/B3 -> 10000 | C4: =1000000/C3 -> 5000 | D4: =1000000/D3 -> 3333.3333 | E4: =1000000/E3 -> 2216.3121 | F4: =1000000/F3 -> 1827.4854 | G4: =1000000/G3 -> 1467.1362 | H4: =1000000/H3 -> 1302.0833 | I4: =1000000/I3 -> 982.7044 | ... L4: =1000000/L3 -> 554.07801
A5: TRUE | B5: INPUT SHEET
A6: GHS | B6: GHS | C6: GHS | D6: GHS | E6: GHS | F6: GHS | G6: D2N | H6: D2N | I6: D2N | J6: D2N | K6: D2N | L6: D2N
A7: VDD_OFF | B7: INPUT SHEET
A8: VDD_OFF | B8: INPUT SHEET
A9: VDD_OFF | B9: INPUT SHEET
A10: 0 | B10: 1 | C10: 1 | D10: 1 | E10: 2 | F10: 2 | G10: 4 | H10: 4 | I10: 7 | J10: 7 | K10: 7 | L10: 7
A11: 2 | B11: 10 | C11: 10 | D11: 10 | E11: 10 | F11: 10 | G11: 10 | H11: 10 | I11: 10 | J11: 10 | K11: 11 | L11: 11
A12: 0 | B12: 2 | C12: 0 | D12: 1 | E12: 1 | F12: 1 | G12: 1 | H12: 1 | I12: 1 | J12: 1 | K12: 1 | L12: 1
A13: FALSE | B13: FALSE | C13: FALSE | D13: FALSE | E13: FALSE | F13: FALSE | G13: FALSE | H13: FALSE | I13: FALSE | J13: FALSE | K13: FALSE | L13: FALSE
A14: 0 | B14: 0 | C14: 0 | D14: 0 | E14: 0 | F14: 0 | G14: 0 | H14: 0 | I14: 2 | J14: 2 | K14: 2 | L14: 2
A15: 0 | B15: 0 | C15: 0 | D15: 0 | E15: 0 | F15: 0 | G15: 0 | H15: 0 | I15: 10 | J15: 9 | K15: 9 | L15: 7
A16: 0 | B16: 0 | C16: 0 | D16: 0 | E16: 0 | F16: 0 | G16: 0 | H16: 0 | I16: 9 | J16: 8 | K16: 7 | L16: 6
A17: 0 | B17: 0 | C17: 0 | D17: 0 | E17: 0 | F17: 0 | G17: 0 | H17: 0 | I17: 6 | J17: 6 | K17: 6 | L17: 6
A18: 0 | B18: 0 | C18: 0 | D18: 0 | E18: 0 | F18: 0 | G18: 0 | H18: 0 | I18: 1 | J18: 1 | K18: 1 | L18: 1
A19: 0 | B19: 0 | C19: 0 | D19: 0 | E19: 0 | F19: 0 | G19: 0 | H19: 0 | I19: 10 | J19: 9 | K19: 9 | L19: 7
A20: 0 | B20: 0 | C20: 0 | D20: 0 | E20: 0 | F20: 0 | G20: 0 | H20: 0 | I20: 0 | J20: 0 | K20: 0 | L20: 0
A21: 0 | B21: 0 | C21: 0 | D21: 0 | E21: 0 | F21: 0 | G21: 0 | H21: 0 | I21: 6 | J21: 6 | K21: 6 | L21: 6
A22: 0 | B22: 1 | C22: 1 | D22: 1 | E22: 1 | F22: 1 | G22: 1 | H22: 1 | I22: 4 | J22: 4 | K22: 4 | L22: 4
A23: 0 | B23: 0 | C23: 0 | D23: 0 | E23: 0 | F23: 0 | G23: 0 | H23: 0 | I23: 0 | J23: 0 | K23: 0 | L23: 0
A24: 0 | B24: 1 | C24: 1 | D24: 1 | E24: 1 | F24: 1 | G24: 1 | H24: 1 | I24: 4 | J24: 4 | K24: 4 | L24: 4
A25: 0 | B25: 0 | C25: 0 | D25: 0 | E25: 0 | F25: 0 | G25: 0 | H25: 0 | I25: 0 | J25: 0 | K25: 0 | L25: 0
A26: 0 | B26: 3 | C26: 3 | D26: 3 | E26: 3 | F26: 3 | G26: 3 | H26: 3 | I26: 3 | J26: 3 | K26: 3 | L26: 3
A27: 0 | B27: 0 | C27: 0 | D27: 0 | E27: 0 | F27: 0 | G27: 0 | H27: 0 | I27: 0 | J27: 0 | K27: 0 | L27: 0
A28: 0 | B28: 3 | C28: 3 | D28: 3 | E28: 3 | F28: 3 | G28: 3 | H28: 3 | I28: 3 | J28: 3 | K28: 3 | L28: 3
A29: 0 | B29: 0 | C29: 0 | D29: 0 | E29: 0 | F29: 0 | G29: 0 | H29: 0 | I29: 0 | J29: 0 | K29: 0 | L29: 0
A30: 0 | B30: 0 | C30: 0 | D30: 0 | E30: 0 | F30: 0 | G30: 0 | H30: 0 | I30: 0 | J30: 0 | K30: 0 | L30: 0
A31: 0 | B31: 0 | C31: 0 | D31: 0 | E31: 0 | F31: 0 | G31: 0 | H31: 0 | I31: 0 | J31: 0 | K31: 0 | L31: 0
A32: 0 | B32: 0 | C32: 0 | D32: 0 | E32: 0 | F32: 0 | G32: 29 | H32: 29 | I32: 29 | J32: 29 | K32: 29 | L32: 29
A33: 0 | B33: 0 | C33: 0 | D33: 0 | E33: 0 | F33: 0 | G33: 29 | H33: 29 | I33: 29 | J33: 29 | K33: 29 | L33: 29
A34: 0 | B34: 0 | C34: 0 | D34: 0 | E34: 0 | F34: 0 | G34: 0 | H34: 0 | I34: 0 | J34: 0 | K34: 0 | L34: 0
A35: 0 | B35: 0 | C35: 0 | D35: 0 | E35: 0 | F35: 0 | G35: 0 | H35: 0 | I35: 0 | J35: 0 | K35: 0 | L35: 0
A36: 0 | B36: 0 | C36: 0 | D36: 0 | E36: 0 | F36: 0 | G36: 0 | H36: 0 | I36: 0 | J36: 0 | K36: 0 | L36: 0
A37: 0 | B37: 0 | C37: 0 | D37: 0 | E37: 0 | F37: 0 | G37: 0 | H37: 0 | I37: 0 | J37: 0 | K37: 0 | L37: 0
A38: 0 | B38: 0 | C38: 0 | D38: 0 | E38: 0 | F38: 0 | G38: 62 | H38: 62 | I38: 62 | J38: 62 | K38: 62 | L38: 62
A39: 0 | B39: 0 | C39: 0 | D39: 0 | E39: 0 | F39: 0 | G39: 0 | H39: 0 | I39: 0 | J39: 0 | K39: 0 | L39: 0
A40: 0 | B40: 0 | C40: 0 | D40: 0 | E40: 0 | F40: 0 | G40: 0 | H40: 0 | I40: 0 | J40: 0 | K40: 0 | L40: 0
...

Sheet ALC
B2: Fixed Values | E2: Modifiable Values | N2: AOP Inputs
B4: MC_CLK | E4: MC Policy | F4: CSPD | G4: IPT | H4: ABSR | J4: S3.n | K4: Entry | L4: Exit | N4: Mapping | P4: Deepest S3 State | Q4: Longest | T4: Calculation Inputs
B5: [MIN,MAX] | C5: [MHz] | E5: [#] | F5: [#mc_clk] | G5: [#mc_clk] | H5: [#xo_clk] | J5: [#] | K5: [#xo_clk] | L5: [#xo_clk] | N5: ALC | O5: MC Policy | P5: S3.n | Q5: Entry | R5: Exit | T5: CSPD | U5: IPT | V5: ABSR | W5: Entry | X5: Exit
B6: MIN | C6: =100/2 -> 50 | E6: 0 | F6: 8 | G6: 128 | H6: 50 | J6: 0 | K6: 0 | L6: 0 | N6: [#] | O6: [#] | P6: [#] | Q6: [us] | R6: [us] | T6: [#mc_clk] | U6: [#mc_clk] | V6: [#xo_clk] | W6: [#xo_clk] | X6: [#xo_clk]
B7: MAX | C7: =1804.8/2 -> 902.4 | E7: 1 | F7: 64 | G7: 128 | H7: 50 | J7: 1 | K7: 5 | L7: 30 | N7: 15 | O7: 3 | P7: 0 | Q7: =(1/MC_CLK_MIN)*T7+(1/19.2)*(V7+W7) -> 10.308333 | R7: =(1/19.2)*X7+0.6 -> 0.6 | T7: =VLOOKUP($O7,MC_POLICY_TABLE,MC_POLICY_COL_CSPD,FALSE) -> 255 | U7: =VLOOKUP($O7,MC_POLICY_TABLE,MC_POLICY_COL_IPT,FALSE) -> 128 | V7: =VLOOKUP($O7,MC_POLICY_TABLE,MC_POLICY_COL_ABSR,FALSE) -> 100 | W7: =VLOOKUP($P7,S3_TABLE,S3_COL_ENTRY,FALSE) -> 0 | X7: =VLOOKUP($P7,S3_TABLE,S3_COL_EXIT,FALSE) -> 0
E8: 2 | F8: 128 | G8: 128 | H8: 100 | J8: 2 | K8: 5 | L8: 1900 | N8: 14 | O8: 2 | P8: 0 | Q8: =(1/MC_CLK_MIN)*T8+(1/19.2)*(V8+W8) -> 7.7683333 | R8: =(1/19.2)*X8+0.6 -> 0.6 | T8: =VLOOKUP($O8,MC_POLICY_TABLE,MC_POLICY_COL_CSPD,FALSE) -> 128 | U8: =VLOOKUP($O8,MC_POLICY_TABLE,MC_POLICY_COL_IPT,FALSE) -> 128 | V8: =VLOOKUP($O8,MC_POLICY_TABLE,MC_POLICY_COL_ABSR,FALSE) -> 100 | W8: =VLOOKUP($P8,S3_TABLE,S3_COL_ENTRY,FALSE) -> 0 | X8: =VLOOKUP($P8,S3_TABLE,S3_COL_EXIT,FALSE) -> 0
E9: 3 | F9: 255 | G9: 128 | H9: 100 | N9: 13 | O9: 1 | P9: 0 | Q9: =(1/MC_CLK_MIN)*T9+(1/19.2)*(V9+W9) -> 3.8841667 | R9: =(1/19.2)*X9+0.6 -> 0.6 | T9: =VLOOKUP($O9,MC_POLICY_TABLE,MC_POLICY_COL_CSPD,FALSE) -> 64 | U9: =VLOOKUP($O9,MC_POLICY_TABLE,MC_POLICY_COL_IPT,FALSE) -> 128 | V9: =VLOOKUP($O9,MC_POLICY_TABLE,MC_POLICY_COL_ABSR,FALSE) -> 50 | W9: =VLOOKUP($P9,S3_TABLE,S3_COL_ENTRY,FALSE) -> 0 | X9: =VLOOKUP($P9,S3_TABLE,S3_COL_EXIT,FALSE) -> 0
K10: 100 | N10: 12 | O10: 0 | P10: 0 | Q10: =(1/MC_CLK_MIN)*T10+(1/19.2)*(V10+W10) -> 2.7641667 | R10: =(1/19.2)*X10+0.6 -> 0.6 | T10: =VLOOKUP($O10,MC_POLICY_TABLE,MC_POLICY_COL_CSPD,FALSE) -> 8 | U10: =VLOOKUP($O10,MC_POLICY_TABLE,MC_POLICY_COL_IPT,FALSE) -> 128 | V10: =VLOOKUP($O10,MC_POLICY_TABLE,MC_POLICY_COL_ABSR,FALSE) -> 50 | W10: =VLOOKUP($P10,S3_TABLE,S3_COL_ENTRY,FALSE) -> 0 | X10: =VLOOKUP($P10,S3_TABLE,S3_COL_EXIT,FALSE) -> 0
K11: 150 | N11: 11 | O11: 3 | P11: 1 | Q11: =(1/MC_CLK_MIN)*T11+(1/19.2)*(V11+W11) -> 10.56875 | R11: =(1/19.2)*X11+0.6 -> 2.1625 | T11: =VLOOKUP($O11,MC_POLICY_TABLE,MC_POLICY_COL_CSPD,FALSE) -> 255 | U11: =VLOOKUP($O11,MC_POLICY_TABLE,MC_POLICY_COL_IPT,FALSE) -> 128 | V11: =VLOOKUP($O11,MC_POLICY_TABLE,MC_POLICY_COL_ABSR,FALSE) -> 100 | W11: =VLOOKUP($P11,S3_TABLE,S3_COL_ENTRY,FALSE) -> 5 | X11: =VLOOKUP($P11,S3_TABLE,S3_COL_EXIT,FALSE) -> 30
K12: changed to | N12: 10 | O12: 2 | P12: 1 | Q12: =(1/MC_CLK_MIN)*T12+(1/19.2)*(V12+W12) -> 8.02875 | R12: =(1/19.2)*X12+0.6 -> 2.1625 | T12: =VLOOKUP($O12,MC_POLICY_TABLE,MC_POLICY_COL_CSPD,FALSE) -> 128 | U12: =VLOOKUP($O12,MC_POLICY_TABLE,MC_POLICY_COL_IPT,FALSE) -> 128 | V12: =VLOOKUP($O12,MC_POLICY_TABLE,MC_POLICY_COL_ABSR,FALSE) -> 100 | W12: =VLOOKUP($P12,S3_TABLE,S3_COL_ENTRY,FALSE) -> 5 | X12: =VLOOKUP($P12,S3_TABLE,S3_COL_EXIT,FALSE) -> 30
K13: 5 | N13: 9 | O13: 1 | P13: 1 | Q13: =(1/MC_CLK_MIN)*T13+(1/19.2)*(V13+W13) -> 4.1445833 | R13: =(1/19.2)*X13+0.6 -> 2.1625 | T13: =VLOOKUP($O13,MC_POLICY_TABLE,MC_POLICY_COL_CSPD,FALSE) -> 64 | U13: =VLOOKUP($O13,MC_POLICY_TABLE,MC_POLICY_COL_IPT,FALSE) -> 128 | V13: =VLOOKUP($O13,MC_POLICY_TABLE,MC_POLICY_COL_ABSR,FALSE) -> 50 | W13: =VLOOKUP($P13,S3_TABLE,S3_COL_ENTRY,FALSE) -> 5 | X13: =VLOOKUP($P13,S3_TABLE,S3_COL_EXIT,FALSE) -> 30
K14: 5 | N14: 8 | O14: 0 | P14: 1 | Q14: =(1/MC_CLK_MIN)*T14+(1/19.2)*(V14+W14) -> 3.0245833 | R14: =(1/19.2)*X14+0.6 -> 2.1625 | T14: =VLOOKUP($O14,MC_POLICY_TABLE,MC_POLICY_COL_CSPD,FALSE) -> 8 | U14: =VLOOKUP($O14,MC_POLICY_TABLE,MC_POLICY_COL_IPT,FALSE) -> 128 | V14: =VLOOKUP($O14,MC_POLICY_TABLE,MC_POLICY_COL_ABSR,FALSE) -> 50 | W14: =VLOOKUP($P14,S3_TABLE,S3_COL_ENTRY,FALSE) -> 5 | X14: =VLOOKUP($P14,S3_TABLE,S3_COL_EXIT,FALSE) -> 30
K15: to match SWC | N15: 7 | O15: 3 | P15: 2 | Q15: =(1/MC_CLK_MIN)*T15+(1/19.2)*(V15+W15) -> 10.56875 | R15: =(1/19.2)*X15+0.6 -> 99.558333 | T15: =VLOOKUP($O15,MC_POLICY_TABLE,MC_POLICY_COL_CSPD,FALSE) -> 255 | U15: =VLOOKUP($O15,MC_POLICY_TABLE,MC_POLICY_COL_IPT,FALSE) -> 128 | V15: =VLOOKUP($O15,MC_POLICY_TABLE,MC_POLICY_COL_ABSR,FALSE) -> 100 | W15: =VLOOKUP($P15,S3_TABLE,S3_COL_ENTRY,FALSE) -> 5 | X15: =VLOOKUP($P15,S3_TABLE,S3_COL_EXIT,FALSE) -> 1900
N16: 6 | O16: 2 | P16: 2 | Q16: =(1/MC_CLK_MIN)*T16+(1/19.2)*(V16+W16) -> 8.02875 | R16: =(1/19.2)*X16+0.6 -> 99.558333 | T16: =VLOOKUP($O16,MC_POLICY_TABLE,MC_POLICY_COL_CSPD,FALSE) -> 128 | U16: =VLOOKUP($O16,MC_POLICY_TABLE,MC_POLICY_COL_IPT,FALSE) -> 128 | V16: =VLOOKUP($O16,MC_POLICY_TABLE,MC_POLICY_COL_ABSR,FALSE) -> 100 | W16: =VLOOKUP($P16,S3_TABLE,S3_COL_ENTRY,FALSE) -> 5 | X16: =VLOOKUP($P16,S3_TABLE,S3_COL_EXIT,FALSE) -> 1900
N17: 5 | O17: 1 | P17: 2 | Q17: =(1/MC_CLK_MIN)*T17+(1/19.2)*(V17+W17) -> 4.1445833 | R17: =(1/19.2)*X17+0.6 -> 99.558333 | T17: =VLOOKUP($O17,MC_POLICY_TABLE,MC_POLICY_COL_CSPD,FALSE) -> 64 | U17: =VLOOKUP($O17,MC_POLICY_TABLE,MC_POLICY_COL_IPT,FALSE) -> 128 | V17: =VLOOKUP($O17,MC_POLICY_TABLE,MC_POLICY_COL_ABSR,FALSE) -> 50 | W17: =VLOOKUP($P17,S3_TABLE,S3_COL_ENTRY,FALSE) -> 5 | X17: =VLOOKUP($P17,S3_TABLE,S3_COL_EXIT,FALSE) -> 1900
N18: 4 | O18: 0 | P18: 2 | Q18: =(1/MC_CLK_MIN)*T18+(1/19.2)*(V18+W18) -> 3.0245833 | R18: =(1/19.2)*X18+0.6 -> 99.558333 | T18: =VLOOKUP($O18,MC_POLICY_TABLE,MC_POLICY_COL_CSPD,FALSE) -> 8 | U18: =VLOOKUP($O18,MC_POLICY_TABLE,MC_POLICY_COL_IPT,FALSE) -> 128 | V18: =VLOOKUP($O18,MC_POLICY_TABLE,MC_POLICY_COL_ABSR,FALSE) -> 50 | W18: =VLOOKUP($P18,S3_TABLE,S3_COL_ENTRY,FALSE) -> 5 | X18: =VLOOKUP($P18,S3_TABLE,S3_COL_EXIT,FALSE) -> 1900
N19: 3 | O19: 3 | P19: 0 | Q19: 0 | R19: 0
N20: 2 | O20: 2 | P20: 0 | Q20: 0 | R20: 0
N21: 1 | O21: 1 | P21: 0 | Q21: 0 | R21: 0
N22: 0 | O22: 0 | P22: 0 | Q22: 0 | R22: 0

Sheet INPUT
B2: AC Timing | C2: ns | D2: nCK | E2: Derate | G2: Clock Plan
B3: tZQLAT | C3: 30 | D3: 8 | G3: Frequency (MHz) | H3: =STRUCT!B3 -> 100 | I3: =STRUCT!C3 -> 200 | J3: =STRUCT!D3 -> 300 | K3: =STRUCT!E3 -> 451.2 | L3: =STRUCT!F3 -> 547.2 | M3: =STRUCT!G3 -> 681.6 | N3: =STRUCT!H3 -> 768 | O3: =STRUCT!I3 -> 1017.6 | ... R3: =STRUCT!L3 -> 1804.8
B4: tSR | C4: 15 | D4: 3 | G4: Frequency Enabled | H4: TRUE | I4: TRUE | J4: TRUE | K4: TRUE | L4: TRUE | M4: TRUE | N4: TRUE | O4: TRUE | P4: TRUE | Q4: TRUE | R4: TRUE
B5: tXSR | C5: 7.5 | D5: 2 | G5: Minimum Voltage for VDDCX Rail (plan) | H5: MIN_SVS | I5: MIN_SVS | J5: MIN_SVS | K5: LOW_SVS | L5: SVS | M5: SVS | N5: SVS | O5: SVS_L1 | P5: NOMINAL | Q5: NOMINAL | R5: TURBO
B6: tXSR_abort | C6: 17.5 | D6: 1 | G6: Minimum Voltage for VDDMX Rail (plan) | H6: NOMINAL | I6: NOMINAL | J6: NOMINAL | K6: NOMINAL | L6: NOMINAL | M6: NOMINAL | N6: NOMINAL | O6: NOMINAL | P6: NOMINAL | Q6: NOMINAL | R6: TURBO
B7: tXP | C7: 7.5 | D7: 5 | G7: Minimum Voltage for VDDA (plan) | H7: MIN_SVS | I7: MIN_SVS | J7: MIN_SVS | K7: LOW_SVS | L7: SVS | M7: SVS | N7: SVS | O7: SVS_L1 | P7: NOMINAL | Q7: NOMINAL | R7: TURBO
B8: tCCD | D8: 8
B9: tRTP | C9: 7.5 | D9: 8 | G9: Safe Mode
B10: tRCD | C10: 18 | D10: 4 | E10: TRUE | G10: Enable Self Refresh Mode | H10: TRUE
B11: tRPpb | C11: 18 | D11: 4 | E11: TRUE | G11: Enable Refresh Rate Polling | H11: TRUE
B12: tRPab | C12: 21 | D12: 4 | E12: TRUE | G12: Enable Periodic ZQ Calibration | H12: TRUE
B13: tRAS | C13: 42 | D13: 3 | E13: TRUE | G13: Enable Periodic Training | H13: TRUE
B14: tRRD | C14: 10 | D14: 4 | E14: TRUE | G14: Enable LPDDR4Y Low Power CA Buffer Support | H14: TRUE
B15: tPPD | D15: 4 | G15: Enable LPDDR4Y Single-Ended Clock Support | H15: FALSE
B16: tFAW | C16: 40 | D16: 1 | G16: Enable Base Logging | H16: TRUE
B17: tDQSCK (min) | C17: 1.5 | D17: 1 | G17: Enable Extended LLCC Logging | H17: FALSE
B18: tDQSCK (max) | C18: 3.5 | D18: 1 | G18: Enable Extended MC Logging | H18: FALSE
B19: tFC | C19: 250 | D19: 1 | G19: Enable Extended PHY Logging | H19: FALSE
B20: tREFI | C20: =3904*1 -> 3904
B21: tMRR | C21: 14 | D21: 8
B22: tMRW | C22: 10 | D22: 10
B23: tMRD | C23: 14 | D23: 10
B24: tODTon (min) | C24: 1.5 | D24: 1
B25: tODTon (max) | C25: 3.5 | D25: 1
B26: tODToff (min) | C26: 1.5 | D26: 1
B27: tODToff (max) | C27: 3.5 | D27: 1
B28: tCKE | C28: 7.5 | D28: 4
B29: tCMDCKE | C29: 1.75 | D29: 3
B30: tCKELCK | C30: 7.5 | D30: 5
B31: tCKCKEH | C31: 1.75 | D31: 5
B32: tMRWCKEL | C32: 14 | D32: 10

Sheet SWCs
A2: Block Name | B2: Relative Address | C2: Register | D2: Recommended Settings | E2: Default | F2: PoR Source
A3: CBU_TOP | B3: 00000230 | C3: CBU_TOP_PG_MGMNT_CFG_0 | D3: 00040010 | E3: 007F0010 | F3: F000FFFF
A4: CBU_TOP | B4: 00000234 | C4: CBU_TOP_PG_MGMNT_CFG_1 | D4: 00040010 | E4: 007F0010 | F4: F000FFFF
A5: CBU_TOP | B5: 00000238 | C5: CBU_TOP_PG_MGMNT_CFG_2 | D5: 00040010 | E5: 007F0010 | F5: F000FFFF
A6: CBU_TOP | B6: 0000023c | C6: CBU_TOP_PG_MGMNT_CFG_3 | D6: 00040010 | E6: 007F0010 | F6: F000FFFF
A7: DDR_CC | B7: 00000598 | C7: DDRCC_SPM_FAL_INDX_TMR_CFG0 | D7: 0x05050505 | E7: 0x00000000 | F7: 0xFFFF0000
A8: DTC | B8: 00000100 | C8: DTC_RANK_TIMING_CFG_TFAW | D8: 00109C40 | E8: 00109C40 | F8: 0
A9: DTC | B9: 00000104 | C9: DTC_RANK_TIMING_CFG_TMRD | D9: 00A036B0 | E9: 00A036B0 | F9: 0
A10: DTC | B10: 00000108 | C10: DTC_RANK_TIMING_CFG_TMRR | D10: 008036B0 | E10: 00A036B0 | F10: 0
A11: DTC | B11: 0000010c | C11: DTC_RANK_TIMING_CFG_TMRW | D11: 00A02710 | E11: 00A036B0 | F11: 0
A12: DTC | B12: 00000110 | C12: DTC_RANK_TIMING_CFG_TPPD | D12: 00400000 | E12: 00400000 | F12: 0
A13: DTC | B13: 00000134 | C13: DTC_RANK_TIMING_CFG_TRP_AB | D13: 10405208 | E13: 10405208 | F13: 0
... A50: SHKE | B50: 0000030c | C50: SHKE_HW_SELF_REFRESH_TIMER_CTRL_3 | D50: 00000032 | E50: 00000000 | F50: FFFF0000

Sheet ALCs
A1: Block Name | B1: Register | C1: Recommended Settings | D1: PoR Source | F1: IN_PS | G1: MIN_CK | H1: DERATE
A2: DTC | B2: DTC_RANK_TIMING_CFG_TZQLAT | C2: =DEC2HEX(2^0*MOD(INPUT!C3*1000,2^F2)+2^20*MOD(INPUT!D3,2^G2)+2^28*MOD(INPUT!E3,2^H2),8) -> 00807530 | D2: FFFFFFFF | F2: 17 | G2: 4
A3: DTC | B3: DTC_SHKE_TIMING_CFG_TSR | C3: =DEC2HEX(2^0*MOD(INPUT!C4*1000,2^F3)+2^20*MOD(INPUT!D4,2^G3)+2^28*MOD(INPUT!E4,2^H3),8) -> 00303A98 | D3: FFFFFFFF | F3: 16 | G3: 4
A4: DTC | B4: DTC_RANK_TIMING_CFG_TXSR | C4: =DEC2HEX(2^0*MOD(INPUT!C5*1000,2^F4)+2^20*MOD(INPUT!D5,2^G4)+2^28*MOD(INPUT!E5,2^H4),8) -> 00201D4C | D4: FFFFFFFF | F4: 15 | G4: 4
A5: DTC | B5: DTC_RANK_TIMING_CFG_TXSR_ABORT | C5: =DEC2HEX(2^0*MOD(INPUT!C6*1000,2^F5)+2^20*MOD(INPUT!D6,2^G5)+2^28*MOD(INPUT!E6,2^H5),8) -> 0010445C | D5: FFFFFFFF | F5: 17 | G5: 4
A6: DTC | B6: DTC_PD_TIMING_CFG_TXP | C6: =DEC2HEX(2^0*MOD(INPUT!C7*1000,2^F6)+2^20*MOD(INPUT!D7,2^G6)+2^28*MOD(INPUT!E7,2^H6),8) -> 00501D4C | D6: FFFFFFFF | F6: 15 | G6: 8
A7: DTC | B7: DTC_COL_TIMING_CFG_TCCD | C7: =DEC2HEX(2^0*MOD(INPUT!C8*1000,2^F7)+2^20*MOD(INPUT!D8,2^G7)+2^28*MOD(INPUT!E8,2^H7),8) -> 00800000 | D7: FFFFFFFF | G7: 5
A8: DTC | B8: DTC_BANK_TIMING_CFG_TRTP | C8: =DEC2HEX(2^0*MOD(INPUT!C9*1000,2^F8)+2^20*MOD(INPUT!D9,2^G8)+2^28*MOD(INPUT!E9,2^H8),8) -> 00801D4C | D8: FFFFFFFF | F8: 15 | G8: 4
A9: DTC | B9: DTC_BANK_TIMING_CFG_TRCD | C9: =DEC2HEX(2^0*MOD(INPUT!C10*1000,2^F9)+2^20*MOD(INPUT!D10,2^G9)+2^28*MOD(INPUT!E10,2^H9),8) -> 10404650 | D9: FFFFFFFF | F9: 17 | G9: 4 | H9: 1
A10: DTC | B10: DTC_BANK_TIMING_CFG_TRP_PB | C10: =DEC2HEX(2^0*MOD(INPUT!C11*1000,2^F10)+2^20*MOD(INPUT!D11,2^G10)+2^28*MOD(INPUT!E11,2^H10),8) -> 10404650 | D10: FFFFFFFF | F10: 17 | G10: 4 | H10: 1
A11: DTC | B11: DTC_RANK_TIMING_CFG_TRP_AB | C11: =DEC2HEX(2^0*MOD(INPUT!C12*1000,2^F11)+2^20*MOD(INPUT!D12,2^G11)+2^28*MOD(INPUT!E12,2^H11),8) -> 10405208 | D11: FFFFFFFF | F11: 17 | G11: 4 | H11: 1
A12: DTC | B12: DTC_BANK_TIMING_CFG_TRASMIN | C12: =DEC2HEX(2^0*MOD(INPUT!C13*1000,2^F12)+2^20*MOD(INPUT!D13,2^G12)+2^28*MOD(INPUT!E13,2^H12),8) -> 1030A410 | D12: FFFFFFFF | F12: 18 | G12: 4 | H12: 1
A13: DTC | B13: DTC_RANK_TIMING_CFG_TRRD | C13: =DEC2HEX(2^0*MOD(INPUT!C14*1000,2^F13)+2^20*MOD(INPUT!D14,2^G13)+2^28*MOD(INPUT!E14,2^H13),8) -> 10402710 | D13: FFFFFFFF | F13: 16 | G13: 4 | H13: 1
A14: DTC | B14: DTC_RANK_TIMING_CFG_TPPD | C14: =DEC2HEX(2^0*MOD(INPUT!C15*1000,2^F14)+2^20*MOD(INPUT!D15,2^G14)+2^28*MOD(INPUT!E15,2^H14),8) -> 00400000 | D14: FFFFFFFF | G14: 4
A15: DTC | B15: DTC_RANK_TIMING_CFG_TFAW | C15: =DEC2HEX(2^0*MOD(INPUT!C16*1000,2^F15)+2^20*MOD(INPUT!D16,2^G15)+2^28*MOD(INPUT!E16,2^H15),8) -> 00109C40 | D15: FFFFFFFF | F15: 18 | G15: 4
A16: DTC | B16: DTC_COL_TIMING_CFG_TDQSCKMIN | C16: =DEC2HEX(2^0*MOD(INPUT!C17*1000,2^F16)+2^20*MOD(INPUT!D17,2^G16)+2^28*MOD(INPUT!E17,2^H16),8) -> 001005DC | D16: FFFFFFFF | F16: 13 | G16: 4
A17: DTC | B17: DTC_COL_TIMING_CFG_TDQSCKMAX | C17: =DEC2HEX(2^0*MOD(INPUT!C18*1000,2^F17)+2^20*MOD(INPUT!D18,2^G17)+2^28*MOD(INPUT!E18,2^H17),8) -> 00100DAC | D17: FFFFFFFF | F17: 14 | G17: 4
A18: DTC | B18: DTC_SHKE_TIMING_CFG_TFC | C18: =DEC2HEX(2^0*MOD(INPUT!C19*1000,2^F18)+2^20*MOD(INPUT!D19,2^G18)+2^28*MOD(INPUT!E19,2^H18),8) -> 0013D090 | D18: FFFFFFFF | F18: 20 | G18: 8
A19: SHKE | B19: SHKE_REFRESH_TIMER_CTRL_RANK_0 | C19: =DEC2HEX(2^0*MOD(INPUT!C20/(1000/19.2),2^F19)+2^20*MOD(INPUT!D20,2^G19)+2^28*MOD(INPUT!E20,2^H19),8) -> 0000004A | D19: 0000FFFF | F19: 16
A20: SHKE | B20: SHKE_REFRESH_TIMER_CTRL_RANK_1 | C20: =DEC2HEX(2^0*MOD(INPUT!C20/(1000/19.2),2^F19)+2^20*MOD(INPUT!D20,2^G19)+2^28*MOD(INPUT!E20,2^H19),8) -> 0000004A | D20: 0000FFFF | F20: 16
A21: DTC | B21: DTC_RANK_TIMING_CFG_TMRR | C21: =DEC2HEX(2^0*MOD(INPUT!C21*1000,2^F21)+2^20*MOD(INPUT!D21,2^G21)+2^28*MOD(INPUT!E21,2^H21),8) -> 008036B0 | D21: FFFFFFFF | F21: 16 | G21: 4
A22: DTC | B22: DTC_RANK_TIMING_CFG_TMRW | C22: =DEC2HEX(2^0*MOD(INPUT!C22*1000,2^F22)+2^20*MOD(INPUT!D22,2^G22)+2^28*MOD(INPUT!E22,2^H22),8) -> 00A02710 | D22: FFFFFFFF | F22: 16 | G22: 4
A23: DTC | B23: DTC_RANK_TIMING_CFG_TMRD | C23: =DEC2HEX(2^0*MOD(INPUT!C23*1000,2^F23)+2^20*MOD(INPUT!D23,2^G23)+2^28*MOD(INPUT!E23,2^H23),8) -> 00A036B0 | D23: FFFFFFFF | F23: 16 | G23: 4
A24: DTC | B24: DTC_COL_TIMING_CFG_TODTON_MIN | C24: =DEC2HEX(2^0*MOD(INPUT!C24*1000,2^F24)+2^20*MOD(INPUT!D24,2^G24)+2^28*MOD(INPUT!E24,2^H24),8) -> 001005DC | D24: FFFFFFFF | F24: 12 | G24: 4
A25: DTC | B25: DTC_COL_TIMING_CFG_TODTON_MAX | C25: =DEC2HEX(2^0*MOD(INPUT!C25*1000,2^F25)+2^20*MOD(INPUT!D25,2^G25)+2^28*MOD(INPUT!E25,2^H25),8) -> 00100DAC | D25: FFFFFFFF | F25: 13 | G25: 4
A26: DTC | B26: DTC_COL_TIMING_CFG_TODTOFF_MIN | C26: =DEC2HEX(2^0*MOD(INPUT!C26*1000,2^F26)+2^20*MOD(INPUT!D26,2^G26)+2^28*MOD(INPUT!E26,2^H26),8) -> 001005DC | D26: FFFFFFFF | F26: 12 | G26: 4
A27: DTC | B27: DTC_COL_TIMING_CFG_TODTOFF_MAX | C27: =DEC2HEX(2^0*MOD(INPUT!C27*1000,2^F27)+2^20*MOD(INPUT!D27,2^G27)+2^28*MOD(INPUT!E27,2^H27),8) -> 00100DAC | D27: FFFFFFFF | F27: 13 | G27: 4
A28: DTC | B28: DTC_PD_TIMING_CFG_TCKE | C28: =DEC2HEX(2^0*MOD(INPUT!C28*1000,2^F28)+2^20*MOD(INPUT!D28,2^G28)+2^28*MOD(INPUT!E28,2^H28),8) -> 00401D4C | D28: FFFFFFFF | F28: 15 | G28: 8
A29: DTC | B29: DTC_PD_TIMING_CFG_TCMDCKE | C29: =DEC2HEX(2^0*MOD(INPUT!C29*1000,2^F29)+2^20*MOD(INPUT!D29,2^G29)+2^28*MOD(INPUT!E29,2^H29),8) -> 003006D6 | D29: FFFFFFFF | F29: 13 | G29: 8
A30: DTC | B30: DTC_PD_TIMING_CFG_TCKELCK | C30: =DEC2HEX(2^0*MOD(INPUT!C30*1000,2^F30)+2^20*MOD(INPUT!D30,2^G30)+2^28*MOD(INPUT!E30,2^H30),8) -> 00501D4C | D30: FFFFFFFF | F30: 15 | G30: 8
A31: DTC | B31: DTC_PD_TIMING_CFG_TCKCKEH | C31: =DEC2HEX(2^0*MOD(INPUT!C31*1000,2^F31)+2^20*MOD(INPUT!D31,2^G31)+2^28*MOD(INPUT!E31,2^H31),8) -> 005006D6 | D31: FFFFFFFF | F31: 13 | G31: 8
A32: DTC | B32: DTC_PD_TIMING_CFG_TMRWCKEL | C32: =DEC2HEX(2^0*MOD(INPUT!C32*1000,2^F32)+2^20*MOD(INPUT!D32,2^G32)+2^28*MOD(INPUT!E32,2^H32),8) -> 00A036B0 | D32: FFFFFFFF | F32: 16 | G32: 8
A33: CBU_TOP | B33: CBU_TOP_PG_MGMNT_CFG_0 | C33: =DEC2HEX(2^16*MOD(VLOOKUP(0,MC_POLICY_TABLE,MC_POLICY_COL_IPT,FALSE),2^12),8) -> 00800000 | D33: =DEC2HEX(2^16*(2^12-1),8) -> 0FFF0000
A34: CBU_TOP | B34: CBU_TOP_PG_MGMNT_CFG_1 | C34: =DEC2HEX(2^16*MOD(VLOOKUP(1,MC_POLICY_TABLE,MC_POLICY_COL_IPT,FALSE),2^12),8) -> 00800000 | D34: =DEC2HEX(2^16*(2^12-1),8) -> 0FFF0000
A35: CBU_TOP | B35: CBU_TOP_PG_MGMNT_CFG_2 | C35: =DEC2HEX(2^16*MOD(VLOOKUP(2,MC_POLICY_TABLE,MC_POLICY_COL_IPT,FALSE),2^12),8) -> 00800000 | D35: =DEC2HEX(2^16*(2^12-1),8) -> 0FFF0000
A36: CBU_TOP | B36: CBU_TOP_PG_MGMNT_CFG_3 | C36: =DEC2HEX(2^16*MOD(VLOOKUP(3,MC_POLICY_TABLE,MC_POLICY_COL_IPT,FALSE),2^12),8) -> 00800000 | D36: =DEC2HEX(2^16*(2^12-1),8) -> 0FFF0000
A37: MPE | B37: MPE_APM_OPT_CFG_0_CS_0 | C37: =DEC2HEX(2^8*MOD(VLOOKUP(0,MC_POLICY_TABLE,MC_POLICY_COL_CSPD,FALSE),2^8),8) -> 00000800 | D37: =DEC2HEX(2^8*(2^8-1),8) -> 0000FF00
A38: MPE | B38: MPE_APM_OPT_CFG_0_CS_1 | C38: =DEC2HEX(2^8*MOD(VLOOKUP(0,MC_POLICY_TABLE,MC_POLICY_COL_CSPD,FALSE),2^8),8) -> 00000800 | D38: =DEC2HEX(2^8*(2^8-1),8) -> 0000FF00
A39: MPE | B39: MPE_APM_OPT_CFG_1_CS_0 | C39: =DEC2HEX(2^8*MOD(VLOOKUP(1,MC_POLICY_TABLE,MC_POLICY_COL_CSPD,FALSE),2^8),8) -> 00004000 | D39: =DEC2HEX(2^8*(2^8-1),8) -> 0000FF00
A40: MPE | B40: MPE_APM_OPT_CFG_1_CS_1 | C40: =DEC2HEX(2^8*MOD(VLOOKUP(1,MC_POLICY_TABLE,MC_POLICY_COL_CSPD,FALSE),2^8),8) -> 00004000 | D40: =DEC2HEX(2^8*(2^8-1),8) -> 0000FF00
...

Sheet STRUCTb
A1: Block Name | B1: Structure/Array | C1: 0 | D1: 1 | E1: 2 | F1: 3 | G1: 4 | H1: 5 | I1: 6 | J1: 7 | K1: 8 | L1: 9 | M1: 10 | N1: 11 | O1: 12 | P1: 13 | Q1: 14 | R1: 15
A2: AOP_PARAMS | B2: mc_states | C2: =DEC2HEX(STRUCT!A2,8) -> 00000000 | D2: =DEC2HEX(STRUCT!B2,8) -> 00000001 | E2: =DEC2HEX(STRUCT!C2,8) -> 00000002 | F2: =DEC2HEX(STRUCT!D2,8) -> 00000003 | G2: =DEC2HEX(STRUCT!E2,8) -> 00000004 | H2: =DEC2HEX(STRUCT!F2,8) -> 00000005 | I2: =DEC2HEX(STRUCT!G2,8) -> 00000006 | J2: =DEC2HEX(STRUCT!H2,8) -> 00000007 | ... N2: =DEC2HEX(STRUCT!L2,8) -> 0000000B
A3: AOP_PARAMS | B3: mc_states | C3: =DEC2HEX(STRUCT!A3*1000,8) -> 00000000 | D3: =DEC2HEX(STRUCT!B3*1000,8) -> 000186A0 | E3: =DEC2HEX(STRUCT!C3*1000,8) -> 00030D40 | F3: =DEC2HEX(STRUCT!D3*1000,8) -> 000493E0 | G3: =DEC2HEX(STRUCT!E3*1000,8) -> 0006E280 | H3: =DEC2HEX(STRUCT!F3*1000,8) -> 00085980 | I3: =DEC2HEX(STRUCT!G3*1000,8) -> 000A6680 | J3: =DEC2HEX(STRUCT!H3*1000,8) -> 000BB800 | ... N3: =DEC2HEX(STRUCT!L3*1000,8) -> 001B8A00
A4: AOP_PARAMS | B4: mc_states | C4: =DEC2HEX(ROUND(STRUCT!A4,1),8) -> FFFFFFFF | D4: =DEC2HEX(ROUND(STRUCT!B4,1),8) -> 00002710 | E4: =DEC2HEX(ROUND(STRUCT!C4,1),8) -> 00001388 | F4: =DEC2HEX(ROUND(STRUCT!D4,1),8) -> 00000D05 | G4: =DEC2HEX(ROUND(STRUCT!E4,1),8) -> 000008A8 | H4: =DEC2HEX(ROUND(STRUCT!F4,1),8) -> 00000723 | I4: =DEC2HEX(ROUND(STRUCT!G4,1),8) -> 000005BB | J4: =DEC2HEX(ROUND(STRUCT!H4,1),8) -> 00000516 | ... N4: =DEC2HEX(ROUND(STRUCT!L4,1),8) -> 0000022A
A5: AOP_PARAMS | B5: mc_states | C5: =DEC2HEX(IF(STRUCT!A5,1,0),8) -> 00000001 | D5: =DEC2HEX(IF(INPUT!H4,1,0),8) -> 00000001 | E5: =DEC2HEX(IF(INPUT!I4,1,0),8) -> 00000001 | F5: =DEC2HEX(IF(INPUT!J4,1,0),8) -> 00000001 | G5: =DEC2HEX(IF(INPUT!K4,1,0),8) -> 00000001 | H5: =DEC2HEX(IF(INPUT!L4,1,0),8) -> 00000001 | I5: =DEC2HEX(IF(INPUT!M4,1,0),8) -> 00000001 | J5: =DEC2HEX(IF(INPUT!N4,1,0),8) -> 00000001 | K5: =DEC2HEX(IF(INPUT!O4,1,0),8) -> 00000001 | ... N5: =DEC2HEX(IF(INPUT!R4,1,0),8) -> 00000001
A6: AOP_PARAMS | B6: mc_states | C6: =VLOOKUP(STRUCT!A6,ENUM_CLK_MODE,2,FALSE) -> 00000000 | D6: =VLOOKUP(STRUCT!B6,ENUM_CLK_MODE,2,FALSE) -> 00000000 | E6: =VLOOKUP(STRUCT!C6,ENUM_CLK_MODE,2,FALSE) -> 00000000 | F6: =VLOOKUP(STRUCT!D6,ENUM_CLK_MODE,2,FALSE) -> 00000000 | G6: =VLOOKUP(STRUCT!E6,ENUM_CLK_MODE,2,FALSE) -> 00000000 | H6: =VLOOKUP(STRUCT!F6,ENUM_CLK_MODE,2,FALSE) -> 00000000 | I6: =VLOOKUP(STRUCT!G6,ENUM_CLK_MODE,2,FALSE) -> 00000001 | J6: =VLOOKUP(STRUCT!H6,ENUM_CLK_MODE,2,FALSE) -> 00000001 | ... N6: =VLOOKUP(STRUCT!L6,ENUM_CLK_MODE,2,FALSE) -> 00000001
A7: AOP_PARAMS | B7: mc_states | C7: =VLOOKUP(STRUCT!A7,ENUM_VOLTAGE_RAIL,2,FALSE) -> 00000000 | D7: =VLOOKUP(INPUT!H5,ENUM_VOLTAGE_RAIL,2,FALSE) -> 00000030 | E7: =VLOOKUP(INPUT!I5,ENUM_VOLTAGE_RAIL,2,FALSE) -> 00000030 | F7: =VLOOKUP(INPUT!J5,ENUM_VOLTAGE_RAIL,2,FALSE) -> 00000030 | G7: =VLOOKUP(INPUT!K5,ENUM_VOLTAGE_RAIL,2,FALSE) -> 00000040 | H7: =VLOOKUP(INPUT!L5,ENUM_VOLTAGE_RAIL,2,FALSE) -> 00000080 | I7: =VLOOKUP(INPUT!M5,ENUM_VOLTAGE_RAIL,2,FALSE) -> 00000080 | J7: =VLOOKUP(INPUT!N5,ENUM_VOLTAGE_RAIL,2,FALSE) -> 00000080 | K7: =VLOOKUP(INPUT!O5,ENUM_VOLTAGE_RAIL,2,FALSE) -> 000000C0 | ... N7: =VLOOKUP(INPUT!R5,ENUM_VOLTAGE_RAIL,2,FALSE) -> 00000180
A8: AOP_PARAMS | B8: mc_states | C8: =VLOOKUP(STRUCT!A8,ENUM_VOLTAGE_RAIL,2,FALSE) -> 00000000 | D8: =VLOOKUP(INPUT!H6,ENUM_VOLTAGE_RAIL,2,FALSE) -> 00000100 | E8: =VLOOKUP(INPUT!I6,ENUM_VOLTAGE_RAIL,2,FALSE) -> 00000100 | F8: =VLOOKUP(INPUT!J6,ENUM_VOLTAGE_RAIL,2,FALSE) -> 00000100 | G8: =VLOOKUP(INPUT!K6,ENUM_VOLTAGE_RAIL,2,FALSE) -> 00000100 | H8: =VLOOKUP(INPUT!L6,ENUM_VOLTAGE_RAIL,2,FALSE) -> 00000100 | I8: =VLOOKUP(INPUT!M6,ENUM_VOLTAGE_RAIL,2,FALSE) -> 00000100 | J8: =VLOOKUP(INPUT!N6,ENUM_VOLTAGE_RAIL,2,FALSE) -> 00000100 | K8: =VLOOKUP(INPUT!O6,ENUM_VOLTAGE_RAIL,2,FALSE) -> 00000100 | ... N8: =VLOOKUP(INPUT!R6,ENUM_VOLTAGE_RAIL,2,FALSE) -> 00000180
A9: AOP_PARAMS | B9: mc_states | C9: =VLOOKUP(STRUCT!A9,ENUM_VOLTAGE_RAIL,2,FALSE) -> 00000000 | D9: =VLOOKUP(INPUT!H7,ENUM_VOLTAGE_RAIL,2,FALSE) -> 00000030 | E9: =VLOOKUP(INPUT!I7,ENUM_VOLTAGE_RAIL,2,FALSE) -> 00000030 | F9: =VLOOKUP(INPUT!J7,ENUM_VOLTAGE_RAIL,2,FALSE) -> 00000030 | G9: =VLOOKUP(INPUT!K7,ENUM_VOLTAGE_RAIL,2,FALSE) -> 00000040 | H9: =VLOOKUP(INPUT!L7,ENUM_VOLTAGE_RAIL,2,FALSE) -> 00000080 | I9: =VLOOKUP(INPUT!M7,ENUM_VOLTAGE_RAIL,2,FALSE) -> 00000080 | J9: =VLOOKUP(INPUT!N7,ENUM_VOLTAGE_RAIL,2,FALSE) -> 00000080 | K9: =VLOOKUP(INPUT!O7,ENUM_VOLTAGE_RAIL,2,FALSE) -> 000000C0 | ... N9: =VLOOKUP(INPUT!R7,ENUM_VOLTAGE_RAIL,2,FALSE) -> 00000180
A10: AOP_PARAMS | B10: mc_states | C10: =DEC2HEX(STRUCT!A10,8) -> 00000000 | D10: =DEC2HEX(STRUCT!B10,8) -> 00000001 | E10: =DEC2HEX(STRUCT!C10,8) -> 00000001 | F10: =DEC2HEX(STRUCT!D10,8) -> 00000001 | G10: =DEC2HEX(STRUCT!E10,8) -> 00000002 | H10: =DEC2HEX(STRUCT!F10,8) -> 00000002 | I10: =DEC2HEX(STRUCT!G10,8) -> 00000004 | J10: =DEC2HEX(STRUCT!H10,8) -> 00000004 | ... N10: =DEC2HEX(STRUCT!L10,8) -> 00000007
A11: AOP_PARAMS | B11: mc_states | C11: =DEC2HEX(STRUCT!A11,2) -> 02 | D11: =DEC2HEX(STRUCT!B11,2) -> 0A | E11: =DEC2HEX(STRUCT!C11,2) -> 0A | F11: =DEC2HEX(STRUCT!D11,2) -> 0A | G11: =DEC2HEX(STRUCT!E11,2) -> 0A | H11: =DEC2HEX(STRUCT!F11,2) -> 0A | I11: =DEC2HEX(STRUCT!G11,2) -> 0A | J11: =DEC2HEX(STRUCT!H11,2) -> 0A | ... N11: =DEC2HEX(STRUCT!L11,2) -> 0B
A12: AOP_PARAMS | B12: mc_states | C12: =DEC2HEX(STRUCT!A12,2) -> 00 | D12: =DEC2HEX(STRUCT!B12,2) -> 02 | E12: =DEC2HEX(STRUCT!C12,2) -> 00 | F12: =DEC2HEX(STRUCT!D12,2) -> 01 | G12: =DEC2HEX(STRUCT!E12,2) -> 01 | H12: =DEC2HEX(STRUCT!F12,2) -> 01 | I12: =DEC2HEX(STRUCT!G12,2) -> 01 | J12: =DEC2HEX(STRUCT!H12,2) -> 01 | ... N12: =DEC2HEX(STRUCT!L12,2) -> 01
A13: AOP_PARAMS | B13: mc_states | C13: =DEC2HEX(IF(STRUCT!A13,1,0),4) -> 0000 | D13: =DEC2HEX(IF(STRUCT!B13,1,0),4) -> 0000 | E13: =DEC2HEX(IF(STRUCT!C13,1,0),4) -> 0000 | F13: =DEC2HEX(IF(STRUCT!D13,1,0),4) -> 0000 | G13: =DEC2HEX(IF(STRUCT!E13,1,0),4) -> 0000 | H13: =DEC2HEX(IF(STRUCT!F13,1,0),4) -> 0000 | I13: =DEC2HEX(IF(STRUCT!G13,1,0),4) -> 0000 | J13: =DEC2HEX(IF(STRUCT!H13,1,0),4) -> 0000 | ... N13: =DEC2HEX(IF(STRUCT!L13,1,0),4) -> 0000
A14: AOP_PARAMS | B14: shub_states | C14: =DEC2HEX(STRUCT!A66,8) -> 00000000 | D14: =DEC2HEX(STRUCT!B66,8) -> 00000001 | E14: =DEC2HEX(STRUCT!C66,8) -> 00000002 | F14: =DEC2HEX(STRUCT!D66,8) -> 00000003 | G14: =DEC2HEX(STRUCT!E66,8) -> 00000004 | H14: =DEC2HEX(STRUCT!F66,8) -> 00000005 | I14: =DEC2HEX(STRUCT!G66,8) -> 00000006
A15: AOP_PARAMS | B15: shub_states | C15: =DEC2HEX(STRUCT!A67*1000,8) -> 00000000 | D15: =DEC2HEX(STRUCT!B67*1000,8) -> 000249F0 | E15: =DEC2HEX(STRUCT!C67*1000,8) -> 000493E0 | F15: =DEC2HEX(STRUCT!D67*1000,8) -> 00071E44 | G15: =DEC2HEX(STRUCT!E67*1000,8) -> 000927C0 | H15: =DEC2HEX(STRUCT!F67*1000,8) -> 000C4C70 | I15: =DEC2HEX(STRUCT!G67*1000,8) -> 000E3C88
A16: AOP_PARAMS | B16: shub_states | C16: =DEC2HEX(STRUCT!A68,8) -> FFFFFFFF | D16: =DEC2HEX(STRUCT!B68,8) -> 00001A0A | E16: =DEC2HEX(STRUCT!C68,8) -> 00000D05 | F16: =DEC2HEX(STRUCT!D68,8) -> 0000085F | G16: =DEC2HEX(STRUCT!E68,8) -> 00000682 | H16: =DEC2HEX(STRUCT!F68,8) -> 000004D8 | I16: =DEC2HEX(STRUCT!G68,8) -> 0000042F
A17: AOP_PARAMS | B17: shub_states | C17: =DEC2HEX(IF(STRUCT!A69,1,0),8) -> 00000001 | D17: =DEC2HEX(IF(STRUCT!B69,1,0),8) -> 00000001 | E17: =DEC2HEX(IF(STRUCT!C69,1,0),8) -> 00000001 | F17: =DEC2HEX(IF(STRUCT!D69,1,0),8) -> 00000001 | G17: =DEC2HEX(IF(STRUCT!E69,1,0),8) -> 00000001 | H17: =DEC2HEX(IF(STRUCT!F69,1,0),8) -> 00000001 | I17: =DEC2HEX(IF(STRUCT!G69,1,0),8) -> 00000001
A18: AOP_PARAMS | B18: shub_states | C18: =VLOOKUP(STRUCT!A70,ENUM_CLK_MODE,2,FALSE) -> 000000FF | D18: =VLOOKUP(STRUCT!B70,ENUM_CLK_MODE,2,FALSE) -> 000000FF | E18: =VLOOKUP(STRUCT!C70,ENUM_CLK_MODE,2,FALSE) -> 000000FF | F18: =VLOOKUP(STRUCT!D70,ENUM_CLK_MODE,2,FALSE) -> 000000FF | G18: =VLOOKUP(STRUCT!E70,ENUM_CLK_MODE,2,FALSE) -> 000000FF | H18: =VLOOKUP(STRUCT!F70,ENUM_CLK_MODE,2,FALSE) -> 000000FF | I18: =VLOOKUP(STRUCT!G70,ENUM_CLK_MODE,2,FALSE) -> 000000FF
A19: AOP_PARAMS | B19: shub_states | C19: =VLOOKUP(STRUCT!A71,ENUM_VOLTAGE_RAIL,2,FALSE) -> 00000000 | D19: =VLOOKUP(STRUCT!B71,ENUM_VOLTAGE_RAIL,2,FALSE) -> 00000030 | E19: =VLOOKUP(STRUCT!C71,ENUM_VOLTAGE_RAIL,2,FALSE) -> 00000040 | F19: =VLOOKUP(STRUCT!D71,ENUM_VOLTAGE_RAIL,2,FALSE) -> 00000080 | G19: =VLOOKUP(STRUCT!E71,ENUM_VOLTAGE_RAIL,2,FALSE) -> 000000C0 | H19: =VLOOKUP(STRUCT!F71,ENUM_VOLTAGE_RAIL,2,FALSE) -> 00000100 | I19: =VLOOKUP(STRUCT!G71,ENUM_VOLTAGE_RAIL,2,FALSE) -> 00000180
A20: AOP_PARAMS | B20: shub_states | C20: =VLOOKUP(STRUCT!A72,ENUM_VOLTAGE_RAIL,2,FALSE) -> 00000000 | D20: =VLOOKUP(STRUCT!B72,ENUM_VOLTAGE_RAIL,2,FALSE) -> 00000100 | E20: =VLOOKUP(STRUCT!C72,ENUM_VOLTAGE_RAIL,2,FALSE) -> 00000100 | F20: =VLOOKUP(STRUCT!D72,ENUM_VOLTAGE_RAIL,2,FALSE) -> 00000100 | G20: =VLOOKUP(STRUCT!E72,ENUM_VOLTAGE_RAIL,2,FALSE) -> 00000100 | H20: =VLOOKUP(STRUCT!F72,ENUM_VOLTAGE_RAIL,2,FALSE) -> 00000100 | I20: =VLOOKUP(STRUCT!G72,ENUM_VOLTAGE_RAIL,2,FALSE) -> 00000180
A21: AOP_PARAMS | B21: shub_states | C21: =VLOOKUP(STRUCT!A73,ENUM_VOLTAGE_RAIL,2,FALSE) -> 00000000 | D21: =VLOOKUP(STRUCT!B73,ENUM_VOLTAGE_RAIL,2,FALSE) -> 00000000 | E21: =VLOOKUP(STRUCT!C73,ENUM_VOLTAGE_RAIL,2,FALSE) -> 00000000 | F21: =VLOOKUP(STRUCT!D73,ENUM_VOLTAGE_RAIL,2,FALSE) -> 00000000 | G21: =VLOOKUP(STRUCT!E73,ENUM_VOLTAGE_RAIL,2,FALSE) -> 00000000 | H21: =VLOOKUP(STRUCT!F73,ENUM_VOLTAGE_RAIL,2,FALSE) -> 00000000 | I21: =VLOOKUP(STRUCT!G73,ENUM_VOLTAGE_RAIL,2,FALSE) -> 00000000
A22: AOP_PARAMS | B22: shub_states | C22: =DEC2HEX(STRUCT!A74,8) -> 00000009 | D22: =DEC2HEX(STRUCT!B74,8) -> 00000009 | E22: =DEC2HEX(STRUCT!C74,8) -> 00000009 | F22: =DEC2HEX(STRUCT!D74,8) -> 00000009 | G22: =DEC2HEX(STRUCT!E74,8) -> 00000009 | H22: =DEC2HEX(STRUCT!F74,8) -> 00000009 | I22: =DEC2HEX(STRUCT!G74,8) -> 00000009
A23: AOP_PARAMS | B23: shub_states | C23: =DEC2HEX(STRUCT!A75,2) -> 01 | D23: =DEC2HEX(STRUCT!B75,2) -> 06 | E23: =DEC2HEX(STRUCT!C75,2) -> 06 | F23: =DEC2HEX(STRUCT!D75,2) -> 06 | G23: =DEC2HEX(STRUCT!E75,2) -> 06 | H23: =DEC2HEX(STRUCT!F75,2) -> 06 | I23: =DEC2HEX(STRUCT!G75,2) -> 06
A24: AOP_PARAMS | B24: shub_states | C24: =DEC2HEX(STRUCT!A76,2) -> 00 | D24: =DEC2HEX(STRUCT!B76,2) -> 00 | E24: =DEC2HEX(STRUCT!C76,2) -> 01 | F24: =DEC2HEX(STRUCT!D76,2) -> 01 | G24: =DEC2HEX(STRUCT!E76,2) -> 01 | H24: =DEC2HEX(STRUCT!F76,2) -> 01 | I24: =DEC2HEX(STRUCT!G76,2) -> 01
A25: AOP_PARAMS | B25: shub_states | C25: =DEC2HEX(IF(STRUCT!A77,1,0),4) -> 0000 | D25: =DEC2HEX(IF(STRUCT!B77,1,0),4) -> 0000 | E25: =DEC2HEX(IF(STRUCT!C77,1,0),4) -> 0000 | F25: =DEC2HEX(IF(STRUCT!D77,1,0),4) -> 0000 | G25: =DEC2HEX(IF(STRUCT!E77,1,0),4) -> 0000 | H25: =DEC2HEX(IF(STRUCT!F77,1,0),4) -> 0000 | I25: =DEC2HEX(IF(STRUCT!G77,1,0),4) -> 0000
A26: AOP_PARAMS | B26: aop_params | C26: =DEC2HEX(STRUCT!A237,8) -> 0000000C
A27: AOP_PARAMS | B27: alc_timings | C27: =DEC2HEX(ALC!Q22*1000,8) -> 00000000 | D27: =DEC2HEX(ALC!Q21*1000,8) -> 00000000 | E27: =DEC2HEX(ALC!Q20*1000,8) -> 00000000 | F27: =DEC2HEX(ALC!Q19*1000,8) -> 00000000 | G27: =DEC2HEX(ALC!Q18*1000,8) -> 00000BD0 | H27: =DEC2HEX(ALC!Q17*1000,8) -> 00001030 | I27: =DEC2HEX(ALC!Q16*1000,8) -> 00001F5C | J27: =DEC2HEX(ALC!Q15*1000,8) -> 00002948 | K27: =DEC2HEX(ALC!Q14*1000,8) -> 00000BD0 | L27: =DEC2HEX(ALC!Q13*1000,8) -> 00001030 | M27: =DEC2HEX(ALC!Q12*1000,8) -> 00001F5C | N27: =DEC2HEX(ALC!Q11*1000,8) -> 00002948 | O27: =DEC2HEX(ALC!Q10*1000,8) -> 00000ACC | P27: =DEC2HEX(ALC!Q9*1000,8) -> 00000F2C | Q27: =DEC2HEX(ALC!Q8*1000,8) -> 00001E58 | R27: =DEC2HEX(ALC!Q7*1000,8) -> 00002844
A28: AOP_PARAMS | B28: alc_timings | C28: =DEC2HEX(ALC!R22*1000,8) -> 00000000 | D28: =DEC2HEX(ALC!R21*1000,8) -> 00000000 | E28: =DEC2HEX(ALC!R20*1000,8) -> 00000000 | F28: =DEC2HEX(ALC!R19*1000,8) -> 00000000 | G28: =DEC2HEX(ALC!R18*1000,8) -> 000184E6 | H28: =DEC2HEX(ALC!R17*1000,8) -> 000184E6 | I28: =DEC2HEX(ALC!R16*1000,8) -> 000184E6 | J28: =DEC2HEX(ALC!R15*1000,8) -> 000184E6 | K28: =DEC2HEX(ALC!R14*1000,8) -> 00000872 | L28: =DEC2HEX(ALC!R13*1000,8) -> 00000872 | M28: =DEC2HEX(ALC!R12*1000,8) -> 00000872 | N28: =DEC2HEX(ALC!R11*1000,8) -> 00000872 | O28: =DEC2HEX(ALC!R10*1000,8) -> 00000258 | P28: =DEC2HEX(ALC!R9*1000,8) -> 00000258 | Q28: =DEC2HEX(ALC!R8*1000,8) -> 00000258 | R28: =DEC2HEX(ALC!R7*1000,8) -> 00000258
A29: DDR_RUNTIME | B29: hw_self_refresh_enable | C29: =DEC2HEX(IF(INPUT!H10,1,0),2) -> 01
A30: DDR_RUNTIME | B30: hw_self_refresh_enable | C30: =DEC2HEX(IF(INPUT!H10,1,0),2) -> 01
A31: DDR_RUNTIME | B31: hw_self_refresh_enable | C31: =DEC2HEX(IF(INPUT!H10,1,0),2) -> 01
A32: DDR_RUNTIME | B32: hw_self_refresh_enable | C32: =DEC2HEX(IF(INPUT!H10,1,0),2) -> 01
A33: DDR_RUNTIME | B33: ddr_runtime | C33: =DEC2HEX(IF(INPUT!H11,1,0),2) -> 01
A34: DDR_RUNTIME | B34: ddr_runtime | C34: =DEC2HEX(IF(INPUT!H12,1,0),2) -> 01
A35: DDR_RUNTIME | B35: ddr_runtime | C35: =DEC2HEX(IF(INPUT!H13,1,0),2) -> 01
A36: DDR_RUNTIME | B36: ddr_runtime | C36: =DEC2HEX(IF(STRUCT!A228,1,0),2) -> 01
A37: DDR_RUNTIME | B37: ddr_runtime | C37: =DEC2HEX(IF(INPUT!H16,1,0),2) -> 01
A38: DDR_RUNTIME | B38: ddr_runtime | C38: =DEC2HEX(IF(INPUT!H17,1,0),2) -> 00
A39: DDR_RUNTIME | B39: ddr_runtime | C39: =DEC2HEX(IF(INPUT!H18,1,0),2) -> 00
A40: DDR_RUNTIME | B40: ddr_runtime | C40: =DEC2HEX(IF(INPUT!H19,1,0),2) -> 00
...

Sheet AUTO
A1: Scorecard Index | B1: DCB Binary Sub-Block | C1: SWC Sheet | D1: Block Name | E1: C Code Register Offset | F1: Summary Prefix | G1: C Code HWIO Prefix | H1: CMM HWIO Prefixes | I1: Remove Prefix | J1: Header
A2: 0 | B2: DQ_PHY | C2: PHY | D2: DQ_PHY | E2: 0 | F2: DDR_PHY | G2: DDR_PHY | H2: DDRPHY_CHm_DQn<3><1> | I2: 1 | J2: ddr_phy_seq_hwioreg.h
A3: 1 | B3: CA_PHY | C3: PHY | D3: CA_PHY | E3: 0 | F3: DDR_PHY | G3: DDR_PHY | H3: DDRPHY_CHn_CA<3> | I3: 1 | J3: ddr_phy_seq_hwioreg.h
A4: 2 | B4: DDR_CC | C4: PHY | D4: DDR_CC | E4: 0 | F4: DDR_CC | G4: DDR_CC | H4: DDRCC_CH01,DDRCC_CH23 | I4: 1 | J4: ddr_cc_seq_hwioreg.h
A5: 3 | B5: MC | C5: MC | D5: MPE | E5: SEQ_CABO_MPE_OFFSET | F5: MPE | G5: MPE | H5: CABOn_CABO_MPE<3> | I5: 0 | J5: cabo_seq_hwioreg.h
A6: 4 | B6: MC | C6: MC | D6: GLOBAL_SEC | E6: SEQ_CABO_GLOBAL_SEC_OFFSET | F6: GLOBAL_SEC | G6: GLOBAL_SEC | H6: CABOn_CABO_GLOBAL_SEC<3> | I6: 0 | J6: cabo_seq_hwioreg.h
A7: 5 | B7: MC | C7: MC | D7: GLOBAL | E7: SEQ_CABO_GLOBAL_OFFSET | F7: GLOBAL | G7: GLOBAL | H7: CABOn_CABO_GLOBAL<3> | I7: 0 | J7: cabo_seq_hwioreg.h
A8: 6 | B8: MC | C8: MC | D8: ISU | E8: SEQ_CABO_ISU_OFFSET | F8: ISU | G8: ISU | H8: CABOn_CABO_ISU<3> | I8: 0 | J8: cabo_seq_hwioreg.h
A9: 7 | B9: MC | C9: MC | D9: CBU_TOP | E9: SEQ_CABO_CBU_TOP_OFFSET | F9: CBU_TOP | G9: CBU_TOP | H9: CABOn_CABO_CBU_TOP<3> | I9: 0 | J9: cabo_seq_hwioreg.h
A10: 8 | B10: MC | C10: MC | D10: DTC | E10: SEQ_CABO_DTC_OFFSET | F10: DTC | G10: DTC | H10: CABOn_CABO_DTC<3> | I10: 0 | J10: cabo_seq_hwioreg.h
A11: 9 | B11: MC | C11: MC | D11: SHKE | E11: SEQ_CABO_SHKE_OFFSET | F11: SHKE | G11: SHKE | H11: CABOn_CABO_SHKE<3> | I11: 0 | J11: cabo_seq_hwioreg.h
A12: 10 | B12: MC | C12: MC | D12: OSU | E12: SEQ_CABO_OSU_OFFSET | F12: OSU | G12: OSU | H12: CABOn_CABO_OSU<3> | I12: 0 | J12: cabo_seq_hwioreg.h
A13: 11 | B13: MC | C13: MC | D13: INTERRUPT | E13: SEQ_CABO_INTERRUPT_OFFSET | F13: INTERRUPT | G13: INTERRUPT | H13: CABOn_CABO_INTERRUPT<3> | I13: 0 | J13: cabo_seq_hwioreg.h
A14: 12 | B14: MCCC_SLV | C14: MCCC | D14: MCCC_SLV | E14: 0 | F14: MCCC_SLV | G14: MCCC_SLV | H14: MCCC_CHn<3> | I14: 0 | J14: mccc_seq_hwioreg.h
A15: 13 | B15: MCCC_MSTR | C15: MCCC | D15: MCCC_MSTR | E15: 0 | F15: MCCC_MSTR | G15: MCCC_MSTR | H15: MCCC | I15: 0 | J15: mccc_seq_hwioreg.h
A16: 14 | B16: MEMNOC | C16: MEMNOC | D16: MEM_NOC | E16: 0 | F16: MEM_NOC | G16: MEM_NOC | H16: MEMNOC | I16: 0 | J16: mem_noc_seq_hwioreg.h
A17: 15 | B17: LLCC | C17: LLCC | D17: LLCC_TRP | E17: SEQ_LLCC_TRP_OFFSET | F17: LLCC_TRP_LLCC_TRP | G17: LLCC_TRP | H17: LLCCn_LLCC_TRP<3> | I17: 0 | J17: llcc_seq_hwioreg.h
A18: 16 | B18: LLCC | C18: LLCC | D18: LLCC_COMMON | E18: SEQ_LLCC_COMMON_OFFSET | F18: LLCC_COMMON_LLCC_COMMON | G18: LLCC_COMMON | H18: LLCCn_LLCC_COMMON<3> | I18: 0 | J18: llcc_seq_hwioreg.h
A19: 17 | B19: LLCC | C19: LLCC | D19: LLCC_PERFMON | E19: SEQ_LLCC_PERFMON_OFFSET | F19: LLCC_PERFMON_LLCC_PERFMON | G19: LLCC_PERFMON | H19: LLCCn_LLCC_PERFMON<3> | I19: 0 | J19: llcc_seq_hwioreg.h
A20: 18 | B20: LLCC | C20: LLCC | D20: LLCC_FEWC | E20: SEQ_LLCC_FEWC_OFFSET | F20: LLCC_FEWC_LLCC_FEWC | G20: LLCC_FEWC | H20: LLCCn_LLCC_FEWC<3> | I20: 0 | J20: llcc_seq_hwioreg.h
A21: 19 | B21: LLCC | C21: LLCC | D21: LLCC_FEAC | E21: SEQ_LLCC_FEAC_OFFSET | F21: LLCC_FEAC_LLCC_FEAC | G21: LLCC_FEAC | H21: LLCCn_LLCC_FEAC<3> | I21: 0 | J21: llcc_seq_hwioreg.h
A22: 20 | B22: LLCC | C22: LLCC | D22: LLCC_BERC | E22: SEQ_LLCC_BERC_OFFSET | F22: LLCC_BERC_LLCC_BERC | G22: LLCC_BERC | H22: LLCCn_LLCC_BERC<3> | I22: 0 | J22: llcc_seq_hwioreg.h
A23: 21 | B23: LLCC | C23: LLCC | D23: LLCC_FERC | E23: SEQ_LLCC_FERC_OFFSET | F23: LLCC_FERC_LLCC_FERC | G23: LLCC_FERC | H23: LLCCn_LLCC_FERC<3> | I23: 0 | J23: llcc_seq_hwioreg.h
A24: 22 | B24: LLCC | C24: LLCC | D24: LLCC_BIST | E24: SEQ_LLCC_BIST_OFFSET | F24: LLCC_BIST_LLCC_BIST | G24: LLCC_BIST | H24: LLCCn_LLCC_BIST<3> | I24: 0 | J24: llcc_seq_hwioreg.h
A25: 23 | B25: LLCC | C25: LLCC | D25: LLCC_AMON | E25: SEQ_LLCC_AMON_OFFSET | F25: LLCC_AMON_LLCC_AMON | G25: LLCC_AMON | H25: LLCCn_LLCC_AMON<3> | I25: 0 | J25: llcc_seq_hwioreg.h
A26: 24 | B26: LLCC | C26: LLCC | D26: LLCC_PMGR | E26: SEQ_LLCC_PMGR_OFFSET | F26: LLCC_PMGR_LLCC_PMGR | G26: LLCC_PMGR | H26: LLCCn_LLCC_PMGR<3> | I26: 0 | J26: llcc_seq_hwioreg.h
A27: 25 | B27: LLCC | C27: LLCC | D27: LLCC_DRP | E27: SEQ_LLCC_DRP_OFFSET | F27: LLCC_DRP_LLCC_DRP | G27: LLCC_DRP | H27: LLCCn_LLCC_DRP<3> | I27: 0 | J27: llcc_seq_hwioreg.h
... A32: 30 | B32: DDRSS | C32: DDRSS | D32: DDR_SS_REGS | E32: SEQ_DDR_SS_DDR_REG_DDR_SS_REGS_OFFSET | F32: DDR_SS_REGS | G32: DDR_SS_REGS | H32: DDR_REG | I32: 0 | J32: ddr_ss_seq_hwioreg.h

Sheet ENUM
A1: boolean | B1: uint32
A2: FALSE | B2: =DEC2HEX(HEX2DEC("0"),8) -> 00000000
A3: TRUE | B3: =DEC2HEX(HEX2DEC("1"),8) -> 00000001
A5: CLK_MODE | B5: uint32
A6: GHS | B6: =DEC2HEX(HEX2DEC("0"),8) -> 00000000
A7: D2N | B7: =DEC2HEX(HEX2DEC("1"),8) -> 00000001
A8: NA | B8: =DEC2HEX(HEX2DEC("FF"),8) -> 000000FF
A10: VOLTAGE_RAIL | B10: uint32
A11: VDD_OFF | B11: =DEC2HEX(HEX2DEC("0"),8) -> 00000000
A12: VDD_RET | B12: =DEC2HEX(HEX2DEC("10"),8) -> 00000010
A13: MIN_SVS | B13: =DEC2HEX(HEX2DEC("30"),8) -> 00000030
A14: LOW_SVS | B14: =DEC2HEX(HEX2DEC("40"),8) -> 00000040
A15: SVS | B15: =DEC2HEX(HEX2DEC("80"),8) -> 00000080
A16: SVS_L1 | B16: =DEC2HEX(HEX2DEC("C0"),8) -> 000000C0
A17: NOMINAL | B17: =DEC2HEX(HEX2DEC("100"),8) -> 00000100
A18: NOMINAL_L1 | B18: =DEC2HEX(HEX2DEC("140"),8) -> 00000140
A19: NOMINAL_L2 | B19: =DEC2HEX(HEX2DEC("150"),8) -> 00000150
A20: TURBO | B20: =DEC2HEX(HEX2DEC("180"),8) -> 00000180
A21: TURBO_L1 | B21: =DEC2HEX(HEX2DEC("1A0"),8) -> 000001A0
